2020-12-12 10:43:13,243 users.py:65 [INFO] create: {'locale': 'ja', 'name': 'piyo'}
2020-12-12 10:43:13,260 error_handler.py:9 [ERROR] ['Traceback (most recent call last):\n', '  File "/opt/app/lf2/lang/error.py", line 15, in wrapper\n    return wrapper_func(*args, **kwargs)\n', '  File "/opt/app/lf2/serialization/deserializer.py", line 24, in deserialize\n    raise TypeError(f\'"{key}" is required key. from {obj_type}\')\n', 'TypeError: "name" is required key. from <class \'example.webapi.controllers.users.CreateParams\'>\n', '\nThe above exception was the direct cause of the following exception:\n\n', 'Traceback (most recent call last):\n', '  File "/opt/app/lf2/lang/error.py", line 15, in wrapper\n    return wrapper_func(*args, **kwargs)\n', '  File "/opt/app/lf2/api/api.py", line 131, in wrapper\n    for key, arg_anno in func_anno.args.items()\n', '  File "/opt/app/lf2/api/api.py", line 132, in <dictcomp>\n    if key not in path_args\n', '  File "/opt/app/lf2/lang/error.py", line 17, in wrapper\n    raise raise_error() from e\n', 'lf2.serialization.errors.DeserializeError\n', '\nThe above exception was the direct cause of the following exception:\n\n', 'Traceback (most recent call last):\n', '  File "/opt/app/lf2/api/api.py", line 84, in wrapper\n    return runner(*args, **kwargs)\n', '  File "/opt/app/lf2/lang/error.py", line 17, in wrapper\n    raise raise_error() from e\n', 'lf2.api.errors.BadRequestError\n']
2020-12-12 10:43:13,260 error_handler.py:9 [ERROR] ['Traceback (most recent call last):\n', '  File "/opt/app/lf2/lang/error.py", line 15, in wrapper\n    return wrapper_func(*args, **kwargs)\n', '  File "/opt/app/lf2/serialization/deserializer.py", line 24, in deserialize\n    raise TypeError(f\'"{key}" is required key. from {obj_type}\')\n', 'TypeError: "name" is required key. from <class \'example.webapi.controllers.users.CreateParams\'>\n', '\nThe above exception was the direct cause of the following exception:\n\n', 'Traceback (most recent call last):\n', '  File "/opt/app/lf2/lang/error.py", line 15, in wrapper\n    return wrapper_func(*args, **kwargs)\n', '  File "/opt/app/lf2/api/api.py", line 131, in wrapper\n    for key, arg_anno in func_anno.args.items()\n', '  File "/opt/app/lf2/api/api.py", line 132, in <dictcomp>\n    if key not in path_args\n', '  File "/opt/app/lf2/lang/error.py", line 17, in wrapper\n    raise raise_error() from e\n', 'lf2.serialization.errors.DeserializeError\n', '\nThe above exception was the direct cause of the following exception:\n\n', 'Traceback (most recent call last):\n', '  File "/opt/app/lf2/api/api.py", line 84, in wrapper\n    return runner(*args, **kwargs)\n', '  File "/opt/app/lf2/lang/error.py", line 17, in wrapper\n    raise raise_error() from e\n', 'lf2.api.errors.BadRequestError\n']
2020-12-12 10:43:13,279 error_handler.py:15 [ERROR] ['Traceback (most recent call last):\n', '  File "/opt/app/lf2/lang/error.py", line 15, in wrapper\n    return wrapper_func(*args, **kwargs)\n', '  File "/opt/app/lf2/serialization/deserializer.py", line 24, in deserialize\n    raise TypeError(f\'"{key}" is required key. from {obj_type}\')\n', 'TypeError: "name" is required key. from <class \'example.webapi.controllers.users.CreateParams\'>\n', '\nThe above exception was the direct cause of the following exception:\n\n', 'Traceback (most recent call last):\n', '  File "/opt/app/lf2/lang/error.py", line 15, in wrapper\n    return wrapper_func(*args, **kwargs)\n', '  File "/opt/app/lf2/api/api.py", line 131, in wrapper\n    for key, arg_anno in func_anno.args.items()\n', '  File "/opt/app/lf2/api/api.py", line 132, in <dictcomp>\n    if key not in path_args\n', '  File "/opt/app/lf2/lang/error.py", line 17, in wrapper\n    raise raise_error() from e\n', 'lf2.serialization.errors.DeserializeError\n', '\nThe above exception was the direct cause of the following exception:\n\n', 'Traceback (most recent call last):\n', '  File "/opt/app/lf2/api/api.py", line 84, in wrapper\n    return runner(*args, **kwargs)\n', '  File "/opt/app/lf2/lang/error.py", line 17, in wrapper\n    raise raise_error() from e\n', 'lf2.api.errors.BadRequestError\n']
2020-12-12 10:43:13,279 error_handler.py:15 [ERROR] ['Traceback (most recent call last):\n', '  File "/opt/app/lf2/lang/error.py", line 15, in wrapper\n    return wrapper_func(*args, **kwargs)\n', '  File "/opt/app/lf2/serialization/deserializer.py", line 24, in deserialize\n    raise TypeError(f\'"{key}" is required key. from {obj_type}\')\n', 'TypeError: "name" is required key. from <class \'example.webapi.controllers.users.CreateParams\'>\n', '\nThe above exception was the direct cause of the following exception:\n\n', 'Traceback (most recent call last):\n', '  File "/opt/app/lf2/lang/error.py", line 15, in wrapper\n    return wrapper_func(*args, **kwargs)\n', '  File "/opt/app/lf2/api/api.py", line 131, in wrapper\n    for key, arg_anno in func_anno.args.items()\n', '  File "/opt/app/lf2/api/api.py", line 132, in <dictcomp>\n    if key not in path_args\n', '  File "/opt/app/lf2/lang/error.py", line 17, in wrapper\n    raise raise_error() from e\n', 'lf2.serialization.errors.DeserializeError\n', '\nThe above exception was the direct cause of the following exception:\n\n', 'Traceback (most recent call last):\n', '  File "/opt/app/lf2/api/api.py", line 84, in wrapper\n    return runner(*args, **kwargs)\n', '  File "/opt/app/lf2/lang/error.py", line 17, in wrapper\n    raise raise_error() from e\n', 'lf2.api.errors.BadRequestError\n']
2020-12-12 10:43:13,279 error_handler.py:15 [ERROR] ['Traceback (most recent call last):\n', '  File "/opt/app/lf2/lang/error.py", line 15, in wrapper\n    return wrapper_func(*args, **kwargs)\n', '  File "/opt/app/lf2/serialization/deserializer.py", line 24, in deserialize\n    raise TypeError(f\'"{key}" is required key. from {obj_type}\')\n', 'TypeError: "name" is required key. from <class \'example.webapi.controllers.users.CreateParams\'>\n', '\nThe above exception was the direct cause of the following exception:\n\n', 'Traceback (most recent call last):\n', '  File "/opt/app/lf2/lang/error.py", line 15, in wrapper\n    return wrapper_func(*args, **kwargs)\n', '  File "/opt/app/lf2/api/api.py", line 131, in wrapper\n    for key, arg_anno in func_anno.args.items()\n', '  File "/opt/app/lf2/api/api.py", line 132, in <dictcomp>\n    if key not in path_args\n', '  File "/opt/app/lf2/lang/error.py", line 17, in wrapper\n    raise raise_error() from e\n', 'lf2.serialization.errors.DeserializeError\n', '\nThe above exception was the direct cause of the following exception:\n\n', 'Traceback (most recent call last):\n', '  File "/opt/app/lf2/api/api.py", line 84, in wrapper\n    return runner(*args, **kwargs)\n', '  File "/opt/app/lf2/lang/error.py", line 17, in wrapper\n    raise raise_error() from e\n', 'lf2.api.errors.BadRequestError\n']
2020-12-12 10:43:13,289 users.py:48 [INFO] index
2020-12-12 10:43:13,289 users.py:48 [INFO] index
2020-12-12 10:43:13,289 users.py:48 [INFO] index
2020-12-12 10:43:13,289 users.py:48 [INFO] index
2020-12-12 10:43:13,302 users.py:56 [INFO] show: {'locale': 'ja'}
2020-12-12 10:43:13,302 users.py:56 [INFO] show: {'locale': 'ja'}
2020-12-12 10:43:13,302 users.py:56 [INFO] show: {'locale': 'ja'}
2020-12-12 10:43:13,302 users.py:56 [INFO] show: {'locale': 'ja'}
2020-12-12 10:43:13,302 users.py:56 [INFO] show: {'locale': 'ja'}
